Workbook

Sheet Summary
A1: Apollo lunar surface frames: terrain-only candidates
A2: Every 70mm Hasselblad frame from magazines used on the surface during Apollo 11, 12, 14, 15, 16 and 17, screened by text descriptions only. No image has been visually checked yet.
A4: Mission | B4: Tier 1 | C4: Tier 2 | D4: Tier 3 | E4: Excluded | F4: All frames
A5: Apollo 11 | B5: =COUNTIFS('All frames'!$E$2:$E$7074,"T1",'All frames'!$B$2:$B$7074,$H5) -> 19 | C5: =COUNTIFS('All frames'!$E$2:$E$7074,"T2",'All frames'!$B$2:$B$7074,$H5) -> 3 | D5: =COUNTIFS('All frames'!$E$2:$E$7074,"T3",'All frames'!$B$2:$B$7074,$H5) -> 0 | E5: =COUNTIFS('All frames'!$E$2:$E$7074,"EXCLUDE",'All frames'!$B$2:$B$7074,$H5) -> 337 | F5: =SUM(B5:E5) -> 359 | H5: 11
A6: Apollo 12 | B6: =COUNTIFS('All frames'!$E$2:$E$7074,"T1",'All frames'!$B$2:$B$7074,$H6) -> 74 | C6: =COUNTIFS('All frames'!$E$2:$E$7074,"T2",'All frames'!$B$2:$B$7074,$H6) -> 92 | D6: =COUNTIFS('All frames'!$E$2:$E$7074,"T3",'All frames'!$B$2:$B$7074,$H6) -> 0 | E6: =COUNTIFS('All frames'!$E$2:$E$7074,"EXCLUDE",'All frames'!$B$2:$B$7074,$H6) -> 444 | F6: =SUM(B6:E6) -> 610 | H6: 12
A7: Apollo 14 | B7: =COUNTIFS('All frames'!$E$2:$E$7074,"T1",'All frames'!$B$2:$B$7074,$H7) -> 110 | C7: =COUNTIFS('All frames'!$E$2:$E$7074,"T2",'All frames'!$B$2:$B$7074,$H7) -> 16 | D7: =COUNTIFS('All frames'!$E$2:$E$7074,"T3",'All frames'!$B$2:$B$7074,$H7) -> 2 | E7: =COUNTIFS('All frames'!$E$2:$E$7074,"EXCLUDE",'All frames'!$B$2:$B$7074,$H7) -> 322 | F7: =SUM(B7:E7) -> 450 | H7: 14
A8: Apollo 15 | B8: =COUNTIFS('All frames'!$E$2:$E$7074,"T1",'All frames'!$B$2:$B$7074,$H8) -> 340 | C8: =COUNTIFS('All frames'!$E$2:$E$7074,"T2",'All frames'!$B$2:$B$7074,$H8) -> 217 | D8: =COUNTIFS('All frames'!$E$2:$E$7074,"T3",'All frames'!$B$2:$B$7074,$H8) -> 0 | E8: =COUNTIFS('All frames'!$E$2:$E$7074,"EXCLUDE",'All frames'!$B$2:$B$7074,$H8) -> 879 | F8: =SUM(B8:E8) -> 1436 | H8: 15
A9: Apollo 16 | B9: =COUNTIFS('All frames'!$E$2:$E$7074,"T1",'All frames'!$B$2:$B$7074,$H9) -> 458 | C9: =COUNTIFS('All frames'!$E$2:$E$7074,"T2",'All frames'!$B$2:$B$7074,$H9) -> 489 | D9: =COUNTIFS('All frames'!$E$2:$E$7074,"T3",'All frames'!$B$2:$B$7074,$H9) -> 0 | E9: =COUNTIFS('All frames'!$E$2:$E$7074,"EXCLUDE",'All frames'!$B$2:$B$7074,$H9) -> 857 | F9: =SUM(B9:E9) -> 1804 | H9: 16
A10: Apollo 17 | B10: =COUNTIFS('All frames'!$E$2:$E$7074,"T1",'All frames'!$B$2:$B$7074,$H10) -> 465 | C10: =COUNTIFS('All frames'!$E$2:$E$7074,"T2",'All frames'!$B$2:$B$7074,$H10) -> 786 | D10: =COUNTIFS('All frames'!$E$2:$E$7074,"T3",'All frames'!$B$2:$B$7074,$H10) -> 0 | E10: =COUNTIFS('All frames'!$E$2:$E$7074,"EXCLUDE",'All frames'!$B$2:$B$7074,$H10) -> 1163 | F10: =SUM(B10:E10) -> 2414 | H10: 17
A11: Total | B11: =SUM(B5:B10) -> 1466 | C11: =SUM(C5:C10) -> 1603 | D11: =SUM(D5:D10) -> 2 | E11: =SUM(E5:E10) -> 4002 | F11: =SUM(F5:F10) -> 7073
A13: Estimated download size (GB) | B13: Tier 1 | C13: Tier 2 | D13: Tier 1 + 2
A14: Raw 16-bit TIFF (ASU, highest resolution) | B14: =SUMIFS('All frames'!$L$2:$L$7074,'All frames'!$E$2:$E$7074,"T1") -> 786.444 | C14: =SUMIFS('All frames'!$L$2:$L$7074,'All frames'!$E$2:$E$7074,"T2") -> 1310.772 | D14: =B14+C14 -> 2097.216
A15: Processed PNG (ASU) | B15: =SUMIFS('All frames'!$M$2:$M$7074,'All frames'!$E$2:$E$7074,"T1") -> 284.71 | C15: =SUMIFS('All frames'!$M$2:$M$7074,'All frames'!$E$2:$E$7074,"T2") -> 369.23 | D15: =B15+C15 -> 653.94
A16: Size assumption: raw TIFF about 1.36 GB per color frame and 0.35 GB per black-and-white frame; processed PNG about 0.30 GB color and 0.17 GB black-and-white. Measured with HTTP HEAD requests on sample frames from each film type in October 2026; the download script checks the exact size of every file before downloading.
A18: Tier definitions
A19: Tier 1 | B19: Described in at least one source, and no source mentions hardware, people, footprints, tracks, shadows, tools, a window or cabin view, orbit, or a bad exposure. Best candidates, but captions rarely mention footprints or tracks, so many still need a visual check.
A20: Tier 2 | B20: No hard exclusion, but a caution flag: sample documentation (a gnomon is often in frame), taken near the LM, rover or ALSEP site, taken from the moving rover, or a crew member named in a way that may mean they are in the picture.
A21: Tier 3 | B21: No description in any source; content unknown.
A22: Excluded | B22: At least one source describes something you asked to exclude, or the frame was not taken on foot on the surface (LM window, cabin, orbit, or the Apollo 15 stand-up EVA from the LM top hatch). Reasons are listed per frame on the All frames sheet.
A23: Sources
A24: NASA catalog (LPI) | B24: Lunar and Planetary Institute Apollo Image Atlas: https://www.lpi.usra.edu/resources/apollo/catalog/70mm/
A25: ASU scans | B25: Arizona State University March to the Moon (JSC scans): https://tothemoon.im-ldi.com/gallery/Apollo
A26: ALSJ captions | B26: Apollo Lunar Surface Journal image libraries, e.g. https://www.apollojournals.org/alsj/a15/images15.html (captions used for screening only; not reproduced here).

Sheet Magazines
A1: Magazine | B1: Mission | C1: Film | D1: Tier 1 | E1: Tier 2 | F1: Tier 3 | G1: Excluded | H1: Frames
A2: AS11-37 | B2: 11 | C2: color | D2: =COUNTIFS('All frames'!$E$2:$E$7074,"T1",'All frames'!$B$2:$B$7074,$B2,'All frames'!$C$2:$C$7074,"37") -> 0 | E2: =COUNTIFS('All frames'!$E$2:$E$7074,"T2",'All frames'!$B$2:$B$7074,$B2,'All frames'!$C$2:$C$7074,"37") -> 0 | F2: =COUNTIFS('All frames'!$E$2:$E$7074,"T3",'All frames'!$B$2:$B$7074,$B2,'All frames'!$C$2:$C$7074,"37") -> 0 | G2: =COUNTIFS('All frames'!$E$2:$E$7074,"EXCLUDE",'All frames'!$B$2:$B$7074,$B2,'All frames'!$C$2:$C$7074,"37") -> 123 | H2: =SUM(D2:G2) -> 123
A3: AS11-39 | B3: 11 | C3: bw | D3: =COUNTIFS('All frames'!$E$2:$E$7074,"T1",'All frames'!$B$2:$B$7074,$B3,'All frames'!$C$2:$C$7074,"39") -> 0 | E3: =COUNTIFS('All frames'!$E$2:$E$7074,"T2",'All frames'!$B$2:$B$7074,$B3,'All frames'!$C$2:$C$7074,"39") -> 0 | F3: =COUNTIFS('All frames'!$E$2:$E$7074,"T3",'All frames'!$B$2:$B$7074,$B3,'All frames'!$C$2:$C$7074,"39") -> 0 | G3: =COUNTIFS('All frames'!$E$2:$E$7074,"EXCLUDE",'All frames'!$B$2:$B$7074,$B3,'All frames'!$C$2:$C$7074,"39") -> 107 | H3: =SUM(D3:G3) -> 107
A4: AS11-40 | B4: 11 | C4: color | D4: =COUNTIFS('All frames'!$E$2:$E$7074,"T1",'All frames'!$B$2:$B$7074,$B4,'All frames'!$C$2:$C$7074,"40") -> 19 | E4: =COUNTIFS('All frames'!$E$2:$E$7074,"T2",'All frames'!$B$2:$B$7074,$B4,'All frames'!$C$2:$C$7074,"40") -> 3 | F4: =COUNTIFS('All frames'!$E$2:$E$7074,"T3",'All frames'!$B$2:$B$7074,$B4,'All frames'!$C$2:$C$7074,"40") -> 0 | G4: =COUNTIFS('All frames'!$E$2:$E$7074,"EXCLUDE",'All frames'!$B$2:$B$7074,$B4,'All frames'!$C$2:$C$7074,"40") -> 107 | H4: =SUM(D4:G4) -> 129
A5: AS12-46 | B5: 12 | C5: color | D5: =COUNTIFS('All frames'!$E$2:$E$7074,"T1",'All frames'!$B$2:$B$7074,$B5,'All frames'!$C$2:$C$7074,"46") -> 4 | E5: =COUNTIFS('All frames'!$E$2:$E$7074,"T2",'All frames'!$B$2:$B$7074,$B5,'All frames'!$C$2:$C$7074,"46") -> 46 | F5: =COUNTIFS('All frames'!$E$2:$E$7074,"T3",'All frames'!$B$2:$B$7074,$B5,'All frames'!$C$2:$C$7074,"46") -> 0 | G5: =COUNTIFS('All frames'!$E$2:$E$7074,"EXCLUDE",'All frames'!$B$2:$B$7074,$B5,'All frames'!$C$2:$C$7074,"46") -> 104 | H5: =SUM(D5:G5) -> 154
A6: AS12-47 | B6: 12 | C6: color | D6: =COUNTIFS('All frames'!$E$2:$E$7074,"T1",'All frames'!$B$2:$B$7074,$B6,'All frames'!$C$2:$C$7074,"47") -> 1 | E6: =COUNTIFS('All frames'!$E$2:$E$7074,"T2",'All frames'!$B$2:$B$7074,$B6,'All frames'!$C$2:$C$7074,"47") -> 30 | F6: =COUNTIFS('All frames'!$E$2:$E$7074,"T3",'All frames'!$B$2:$B$7074,$B6,'All frames'!$C$2:$C$7074,"47") -> 0 | G6: =COUNTIFS('All frames'!$E$2:$E$7074,"EXCLUDE",'All frames'!$B$2:$B$7074,$B6,'All frames'!$C$2:$C$7074,"47") -> 122 | H6: =SUM(D6:G6) -> 153
A7: AS12-48 | B7: 12 | C7: bw | D7: =COUNTIFS('All frames'!$E$2:$E$7074,"T1",'All frames'!$B$2:$B$7074,$B7,'All frames'!$C$2:$C$7074,"48") -> 4 | E7: =COUNTIFS('All frames'!$E$2:$E$7074,"T2",'All frames'!$B$2:$B$7074,$B7,'All frames'!$C$2:$C$7074,"48") -> 5 | F7: =COUNTIFS('All frames'!$E$2:$E$7074,"T3",'All frames'!$B$2:$B$7074,$B7,'All frames'!$C$2:$C$7074,"48") -> 0 | G7: =COUNTIFS('All frames'!$E$2:$E$7074,"EXCLUDE",'All frames'!$B$2:$B$7074,$B7,'All frames'!$C$2:$C$7074,"48") -> 141 | H7: =SUM(D7:G7) -> 150
A8: AS12-49 | B8: 12 | C8: bw | D8: =COUNTIFS('All frames'!$E$2:$E$7074,"T1",'All frames'!$B$2:$B$7074,$B8,'All frames'!$C$2:$C$7074,"49") -> 65 | E8: =COUNTIFS('All frames'!$E$2:$E$7074,"T2",'All frames'!$B$2:$B$7074,$B8,'All frames'!$C$2:$C$7074,"49") -> 11 | F8: =COUNTIFS('All frames'!$E$2:$E$7074,"T3",'All frames'!$B$2:$B$7074,$B8,'All frames'!$C$2:$C$7074,"49") -> 0 | G8: =COUNTIFS('All frames'!$E$2:$E$7074,"EXCLUDE",'All frames'!$B$2:$B$7074,$B8,'All frames'!$C$2:$C$7074,"49") -> 77 | H8: =SUM(D8:G8) -> 153
A9: AS14-64 | B9: 14 | C9: bw | D9: =COUNTIFS('All frames'!$E$2:$E$7074,"T1",'All frames'!$B$2:$B$7074,$B9,'All frames'!$C$2:$C$7074,"64") -> 45 | E9: =COUNTIFS('All frames'!$E$2:$E$7074,"T2",'All frames'!$B$2:$B$7074,$B9,'All frames'!$C$2:$C$7074,"64") -> 6 | F9: =COUNTIFS('All frames'!$E$2:$E$7074,"T3",'All frames'!$B$2:$B$7074,$B9,'All frames'!$C$2:$C$7074,"64") -> 0 | G9: =COUNTIFS('All frames'!$E$2:$E$7074,"EXCLUDE",'All frames'!$B$2:$B$7074,$B9,'All frames'!$C$2:$C$7074,"64") -> 105 | H9: =SUM(D9:G9) -> 156
A10: AS14-65 | B10: 14 | C10: bw | D10: =COUNTIFS('All frames'!$E$2:$E$7074,"T1",'All frames'!$B$2:$B$7074,$B10,'All frames'!$C$2:$C$7074,"65") -> 0 | E10: =COUNTIFS('All frames'!$E$2:$E$7074,"T2",'All frames'!$B$2:$B$7074,$B10,'All frames'!$C$2:$C$7074,"65") -> 0 | F10: =COUNTIFS('All frames'!$E$2:$E$7074,"T3",'All frames'!$B$2:$B$7074,$B10,'All frames'!$C$2:$C$7074,"65") -> 0 | G10: =COUNTIFS('All frames'!$E$2:$E$7074,"EXCLUDE",'All frames'!$B$2:$B$7074,$B10,'All frames'!$C$2:$C$7074,"65") -> 14 | H10: =SUM(D10:G10) -> 14
A11: AS14-66 | B11: 14 | C11: color | D11: =COUNTIFS('All frames'!$E$2:$E$7074,"T1",'All frames'!$B$2:$B$7074,$B11,'All frames'!$C$2:$C$7074,"66") -> 30 | E11: =COUNTIFS('All frames'!$E$2:$E$7074,"T2",'All frames'!$B$2:$B$7074,$B11,'All frames'!$C$2:$C$7074,"66") -> 2 | F11: =COUNTIFS('All frames'!$E$2:$E$7074,"T3",'All frames'!$B$2:$B$7074,$B11,'All frames'!$C$2:$C$7074,"66") -> 0 | G11: =COUNTIFS('All frames'!$E$2:$E$7074,"EXCLUDE",'All frames'!$B$2:$B$7074,$B11,'All frames'!$C$2:$C$7074,"66") -> 113 | H11: =SUM(D11:G11) -> 145
A12: AS14-67 | B12: 14 | C12: color | D12: =COUNTIFS('All frames'!$E$2:$E$7074,"T1",'All frames'!$B$2:$B$7074,$B12,'All frames'!$C$2:$C$7074,"67") -> 2 | E12: =COUNTIFS('All frames'!$E$2:$E$7074,"T2",'All frames'!$B$2:$B$7074,$B12,'All frames'!$C$2:$C$7074,"67") -> 1 | F12: =COUNTIFS('All frames'!$E$2:$E$7074,"T3",'All frames'!$B$2:$B$7074,$B12,'All frames'!$C$2:$C$7074,"67") -> 0 | G12: =COUNTIFS('All frames'!$E$2:$E$7074,"EXCLUDE",'All frames'!$B$2:$B$7074,$B12,'All frames'!$C$2:$C$7074,"67") -> 30 | H12: =SUM(D12:G12) -> 33
A13: AS14-68 | B13: 14 | C13: bw | D13: =COUNTIFS('All frames'!$E$2:$E$7074,"T1",'All frames'!$B$2:$B$7074,$B13,'All frames'!$C$2:$C$7074,"68") -> 33 | E13: =COUNTIFS('All frames'!$E$2:$E$7074,"T2",'All frames'!$B$2:$B$7074,$B13,'All frames'!$C$2:$C$7074,"68") -> 7 | F13: =COUNTIFS('All frames'!$E$2:$E$7074,"T3",'All frames'!$B$2:$B$7074,$B13,'All frames'!$C$2:$C$7074,"68") -> 2 | G13: =COUNTIFS('All frames'!$E$2:$E$7074,"EXCLUDE",'All frames'!$B$2:$B$7074,$B13,'All frames'!$C$2:$C$7074,"68") -> 60 | H13: =SUM(D13:G13) -> 102
A14: AS15-82 | B14: 15 | C14: bw | D14: =COUNTIFS('All frames'!$E$2:$E$7074,"T1",'All frames'!$B$2:$B$7074,$B14,'All frames'!$C$2:$C$7074,"82") -> 52 | E14: =COUNTIFS('All frames'!$E$2:$E$7074,"T2",'All frames'!$B$2:$B$7074,$B14,'All frames'!$C$2:$C$7074,"82") -> 40 | F14: =COUNTIFS('All frames'!$E$2:$E$7074,"T3",'All frames'!$B$2:$B$7074,$B14,'All frames'!$C$2:$C$7074,"82") -> 0 | G14: =COUNTIFS('All frames'!$E$2:$E$7074,"EXCLUDE",'All frames'!$B$2:$B$7074,$B14,'All frames'!$C$2:$C$7074,"82") -> 79 | H14: =SUM(D14:G14) -> 171
A15: AS15-84 | B15: 15 | C15: bw | D15: =COUNTIFS('All frames'!$E$2:$E$7074,"T1",'All frames'!$B$2:$B$7074,$B15,'All frames'!$C$2:$C$7074,"84") -> 80 | E15: =COUNTIFS('All frames'!$E$2:$E$7074,"T2",'All frames'!$B$2:$B$7074,$B15,'All frames'!$C$2:$C$7074,"84") -> 8 | F15: =COUNTIFS('All frames'!$E$2:$E$7074,"T3",'All frames'!$B$2:$B$7074,$B15,'All frames'!$C$2:$C$7074,"84") -> 0 | G15: =COUNTIFS('All frames'!$E$2:$E$7074,"EXCLUDE",'All frames'!$B$2:$B$7074,$B15,'All frames'!$C$2:$C$7074,"84") -> 30 | H15: =SUM(D15:G15) -> 118
A16: AS15-85 | B16: 15 | C16: bw | D16: =COUNTIFS('All frames'!$E$2:$E$7074,"T1",'All frames'!$B$2:$B$7074,$B16,'All frames'!$C$2:$C$7074,"85") -> 26 | E16: =COUNTIFS('All frames'!$E$2:$E$7074,"T2",'All frames'!$B$2:$B$7074,$B16,'All frames'!$C$2:$C$7074,"85") -> 17 | F16: =COUNTIFS('All frames'!$E$2:$E$7074,"T3",'All frames'!$B$2:$B$7074,$B16,'All frames'!$C$2:$C$7074,"85") -> 0 | G16: =COUNTIFS('All frames'!$E$2:$E$7074,"EXCLUDE",'All frames'!$B$2:$B$7074,$B16,'All frames'!$C$2:$C$7074,"85") -> 134 | H16: =SUM(D16:G16) -> 177
A17: AS15-86 | B17: 15 | C17: color | D17: =COUNTIFS('All frames'!$E$2:$E$7074,"T1",'All frames'!$B$2:$B$7074,$B17,'All frames'!$C$2:$C$7074,"86") -> 2 | E17: =COUNTIFS('All frames'!$E$2:$E$7074,"T2",'All frames'!$B$2:$B$7074,$B17,'All frames'!$C$2:$C$7074,"86") -> 63 | F17: =COUNTIFS('All frames'!$E$2:$E$7074,"T3",'All frames'!$B$2:$B$7074,$B17,'All frames'!$C$2:$C$7074,"86") -> 0 | G17: =COUNTIFS('All frames'!$E$2:$E$7074,"EXCLUDE",'All frames'!$B$2:$B$7074,$B17,'All frames'!$C$2:$C$7074,"86") -> 100 | H17: =SUM(D17:G17) -> 165
A18: AS15-87 | B18: 15 | C18: color | D18: =COUNTIFS('All frames'!$E$2:$E$7074,"T1",'All frames'!$B$2:$B$7074,$B18,'All frames'!$C$2:$C$7074,"87") -> 0 | E18: =COUNTIFS('All frames'!$E$2:$E$7074,"T2",'All frames'!$B$2:$B$7074,$B18,'All frames'!$C$2:$C$7074,"87") -> 46 | F18: =COUNTIFS('All frames'!$E$2:$E$7074,"T3",'All frames'!$B$2:$B$7074,$B18,'All frames'!$C$2:$C$7074,"87") -> 0 | G18: =COUNTIFS('All frames'!$E$2:$E$7074,"EXCLUDE",'All frames'!$B$2:$B$7074,$B18,'All frames'!$C$2:$C$7074,"87") -> 120 | H18: =SUM(D18:G18) -> 166
A19: AS15-88 | B19: 15 | C19: color | D19: =COUNTIFS('All frames'!$E$2:$E$7074,"T1",'All frames'!$B$2:$B$7074,$B19,'All frames'!$C$2:$C$7074,"88") -> 1 | E19: =COUNTIFS('All frames'!$E$2:$E$7074,"T2",'All frames'!$B$2:$B$7074,$B19,'All frames'!$C$2:$C$7074,"88") -> 18 | F19: =COUNTIFS('All frames'!$E$2:$E$7074,"T3",'All frames'!$B$2:$B$7074,$B19,'All frames'!$C$2:$C$7074,"88") -> 0 | G19: =COUNTIFS('All frames'!$E$2:$E$7074,"EXCLUDE",'All frames'!$B$2:$B$7074,$B19,'All frames'!$C$2:$C$7074,"88") -> 135 | H19: =SUM(D19:G19) -> 154
A20: AS15-89 | B20: 15 | C20: bw | D20: =COUNTIFS('All frames'!$E$2:$E$7074,"T1",'All frames'!$B$2:$B$7074,$B20,'All frames'!$C$2:$C$7074,"89") -> 153 | E20: =COUNTIFS('All frames'!$E$2:$E$7074,"T2",'All frames'!$B$2:$B$7074,$B20,'All frames'!$C$2:$C$7074,"89") -> 7 | F20: =COUNTIFS('All frames'!$E$2:$E$7074,"T3",'All frames'!$B$2:$B$7074,$B20,'All frames'!$C$2:$C$7074,"89") -> 0 | G20: =COUNTIFS('All frames'!$E$2:$E$7074,"EXCLUDE",'All frames'!$B$2:$B$7074,$B20,'All frames'!$C$2:$C$7074,"89") -> 4 | H20: =SUM(D20:G20) -> 164
A21: AS15-90 | B21: 15 | C21: bw | D21: =COUNTIFS('All frames'!$E$2:$E$7074,"T1",'All frames'!$B$2:$B$7074,$B21,'All frames'!$C$2:$C$7074,"90") -> 26 | E21: =COUNTIFS('All frames'!$E$2:$E$7074,"T2",'All frames'!$B$2:$B$7074,$B21,'All frames'!$C$2:$C$7074,"90") -> 14 | F21: =COUNTIFS('All frames'!$E$2:$E$7074,"T3",'All frames'!$B$2:$B$7074,$B21,'All frames'!$C$2:$C$7074,"90") -> 0 | G21: =COUNTIFS('All frames'!$E$2:$E$7074,"EXCLUDE",'All frames'!$B$2:$B$7074,$B21,'All frames'!$C$2:$C$7074,"90") -> 110 | H21: =SUM(D21:G21) -> 150
A22: AS15-92 | B22: 15 | C22: bw | D22: =COUNTIFS('All frames'!$E$2:$E$7074,"T1",'All frames'!$B$2:$B$7074,$B22,'All frames'!$C$2:$C$7074,"92") -> 0 | E22: =COUNTIFS('All frames'!$E$2:$E$7074,"T2",'All frames'!$B$2:$B$7074,$B22,'All frames'!$C$2:$C$7074,"92") -> 4 | F22: =COUNTIFS('All frames'!$E$2:$E$7074,"T3",'All frames'!$B$2:$B$7074,$B22,'All frames'!$C$2:$C$7074,"92") -> 0 | G22: =COUNTIFS('All frames'!$E$2:$E$7074,"EXCLUDE",'All frames'!$B$2:$B$7074,$B22,'All frames'!$C$2:$C$7074,"92") -> 167 | H22: =SUM(D22:G22) -> 171
A23: AS16-105 | B23: 16 | C23: bw | D23: =COUNTIFS('All frames'!$E$2:$E$7074,"T1",'All frames'!$B$2:$B$7074,$B23,'All frames'!$C$2:$C$7074,"105") -> 115 | E23: =COUNTIFS('All frames'!$E$2:$E$7074,"T2",'All frames'!$B$2:$B$7074,$B23,'All frames'!$C$2:$C$7074,"105") -> 44 | F23: =COUNTIFS('All frames'!$E$2:$E$7074,"T3",'All frames'!$B$2:$B$7074,$B23,'All frames'!$C$2:$C$7074,"105") -> 0 | G23: =COUNTIFS('All frames'!$E$2:$E$7074,"EXCLUDE",'All frames'!$B$2:$B$7074,$B23,'All frames'!$C$2:$C$7074,"105") -> 25 | H23: =SUM(D23:G23) -> 184
A24: AS16-106 | B24: 16 | C24: bw | D24: =COUNTIFS('All frames'!$E$2:$E$7074,"T1",'All frames'!$B$2:$B$7074,$B24,'All frames'!$C$2:$C$7074,"106") -> 102 | E24: =COUNTIFS('All frames'!$E$2:$E$7074,"T2",'All frames'!$B$2:$B$7074,$B24,'All frames'!$C$2:$C$7074,"106") -> 42 | F24: =COUNTIFS('All frames'!$E$2:$E$7074,"T3",'All frames'!$B$2:$B$7074,$B24,'All frames'!$C$2:$C$7074,"106") -> 0 | G24: =COUNTIFS('All frames'!$E$2:$E$7074,"EXCLUDE",'All frames'!$B$2:$B$7074,$B24,'All frames'!$C$2:$C$7074,"106") -> 38 | H24: =SUM(D24:G24) -> 182
A25: AS16-107 | B25: 16 | C25: color | D25: =COUNTIFS('All frames'!$E$2:$E$7074,"T1",'All frames'!$B$2:$B$7074,$B25,'All frames'!$C$2:$C$7074,"107") -> 15 | E25: =COUNTIFS('All frames'!$E$2:$E$7074,"T2",'All frames'!$B$2:$B$7074,$B25,'All frames'!$C$2:$C$7074,"107") -> 49 | F25: =COUNTIFS('All frames'!$E$2:$E$7074,"T3",'All frames'!$B$2:$B$7074,$B25,'All frames'!$C$2:$C$7074,"107") -> 0 | G25: =COUNTIFS('All frames'!$E$2:$E$7074,"EXCLUDE",'All frames'!$B$2:$B$7074,$B25,'All frames'!$C$2:$C$7074,"107") -> 101 | H25: =SUM(D25:G25) -> 165
A26: AS16-108 | B26: 16 | C26: bw | D26: =COUNTIFS('All frames'!$E$2:$E$7074,"T1",'All frames'!$B$2:$B$7074,$B26,'All frames'!$C$2:$C$7074,"108") -> 42 | E26: =COUNTIFS('All frames'!$E$2:$E$7074,"T2",'All frames'!$B$2:$B$7074,$B26,'All frames'!$C$2:$C$7074,"108") -> 68 | F26: =COUNTIFS('All frames'!$E$2:$E$7074,"T3",'All frames'!$B$2:$B$7074,$B26,'All frames'!$C$2:$C$7074,"108") -> 0 | G26: =COUNTIFS('All frames'!$E$2:$E$7074,"EXCLUDE",'All frames'!$B$2:$B$7074,$B26,'All frames'!$C$2:$C$7074,"108") -> 52 | H26: =SUM(D26:G26) -> 162
A27: AS16-109 | B27: 16 | C27: bw | D27: =COUNTIFS('All frames'!$E$2:$E$7074,"T1",'All frames'!$B$2:$B$7074,$B27,'All frames'!$C$2:$C$7074,"109") -> 29 | E27: =COUNTIFS('All frames'!$E$2:$E$7074,"T2",'All frames'!$B$2:$B$7074,$B27,'All frames'!$C$2:$C$7074,"109") -> 17 | F27: =COUNTIFS('All frames'!$E$2:$E$7074,"T3",'All frames'!$B$2:$B$7074,$B27,'All frames'!$C$2:$C$7074,"109") -> 0 | G27: =COUNTIFS('All frames'!$E$2:$E$7074,"EXCLUDE",'All frames'!$B$2:$B$7074,$B27,'All frames'!$C$2:$C$7074,"109") -> 73 | H27: =SUM(D27:G27) -> 119
A28: AS16-110 | B28: 16 | C28: bw | D28: =COUNTIFS('All frames'!$E$2:$E$7074,"T1",'All frames'!$B$2:$B$7074,$B28,'All frames'!$C$2:$C$7074,"110") -> 32 | E28: =COUNTIFS('All frames'!$E$2:$E$7074,"T2",'All frames'!$B$2:$B$7074,$B28,'All frames'!$C$2:$C$7074,"110") -> 20 | F28: =COUNTIFS('All frames'!$E$2:$E$7074,"T3",'All frames'!$B$2:$B$7074,$B28,'All frames'!$C$2:$C$7074,"110") -> 0 | G28: =COUNTIFS('All frames'!$E$2:$E$7074,"EXCLUDE",'All frames'!$B$2:$B$7074,$B28,'All frames'!$C$2:$C$7074,"110") -> 117 | H28: =SUM(D28:G28) -> 169
A29: AS16-111 | B29: 16 | C29: bw | D29: =COUNTIFS('All frames'!$E$2:$E$7074,"T1",'All frames'!$B$2:$B$7074,$B29,'All frames'!$C$2:$C$7074,"111") -> 0 | E29: =COUNTIFS('All frames'!$E$2:$E$7074,"T2",'All frames'!$B$2:$B$7074,$B29,'All frames'!$C$2:$C$7074,"111") -> 0 | F29: =COUNTIFS('All frames'!$E$2:$E$7074,"T3",'All frames'!$B$2:$B$7074,$B29,'All frames'!$C$2:$C$7074,"111") -> 0 | G29: =COUNTIFS('All frames'!$E$2:$E$7074,"EXCLUDE",'All frames'!$B$2:$B$7074,$B29,'All frames'!$C$2:$C$7074,"111") -> 159 | H29: =SUM(D29:G29) -> 159
A30: AS16-112 | B30: 16 | C30: bw | D30: =COUNTIFS('All frames'!$E$2:$E$7074,"T1",'All frames'!$B$2:$B$7074,$B30,'All frames'!$C$2:$C$7074,"112") -> 71 | E30: =COUNTIFS('All frames'!$E$2:$E$7074,"T2",'All frames'!$B$2:$B$7074,$B30,'All frames'!$C$2:$C$7074,"112") -> 1 | F30: =COUNTIFS('All frames'!$E$2:$E$7074,"T3",'All frames'!$B$2:$B$7074,$B30,'All frames'!$C$2:$C$7074,"112") -> 0 | G30: =COUNTIFS('All frames'!$E$2:$E$7074,"EXCLUDE",'All frames'!$B$2:$B$7074,$B30,'All frames'!$C$2:$C$7074,"112") -> 14 | H30: =SUM(D30:G30) -> 86
A31: AS16-113 | B31: 16 | C31: color | D31: =COUNTIFS('All frames'!$E$2:$E$7074,"T1",'All frames'!$B$2:$B$7074,$B31,'All frames'!$C$2:$C$7074,"113") -> 0 | E31: =COUNTIFS('All frames'!$E$2:$E$7074,"T2",'All frames'!$B$2:$B$7074,$B31,'All frames'!$C$2:$C$7074,"113") -> 23 | F31: =COUNTIFS('All frames'!$E$2:$E$7074,"T3",'All frames'!$B$2:$B$7074,$B31,'All frames'!$C$2:$C$7074,"113") -> 0 | G31: =COUNTIFS('All frames'!$E$2:$E$7074,"EXCLUDE",'All frames'!$B$2:$B$7074,$B31,'All frames'!$C$2:$C$7074,"113") -> 81 | H31: =SUM(D31:G31) -> 104
A32: AS16-114 | B32: 16 | C32: color | D32: =COUNTIFS('All frames'!$E$2:$E$7074,"T1",'All frames'!$B$2:$B$7074,$B32,'All frames'!$C$2:$C$7074,"114") -> 19 | E32: =COUNTIFS('All frames'!$E$2:$E$7074,"T2",'All frames'!$B$2:$B$7074,$B32,'All frames'!$C$2:$C$7074,"114") -> 20 | F32: =COUNTIFS('All frames'!$E$2:$E$7074,"T3",'All frames'!$B$2:$B$7074,$B32,'All frames'!$C$2:$C$7074,"114") -> 0 | G32: =COUNTIFS('All frames'!$E$2:$E$7074,"EXCLUDE",'All frames'!$B$2:$B$7074,$B32,'All frames'!$C$2:$C$7074,"114") -> 49 | H32: =SUM(D32:G32) -> 88
A33: AS16-115 | B33: 16 | C33: color | D33: =COUNTIFS('All frames'!$E$2:$E$7074,"T1",'All frames'!$B$2:$B$7074,$B33,'All frames'!$C$2:$C$7074,"115") -> 0 | E33: =COUNTIFS('All frames'!$E$2:$E$7074,"T2",'All frames'!$B$2:$B$7074,$B33,'All frames'!$C$2:$C$7074,"115") -> 77 | F33: =COUNTIFS('All frames'!$E$2:$E$7074,"T3",'All frames'!$B$2:$B$7074,$B33,'All frames'!$C$2:$C$7074,"115") -> 0 | G33: =COUNTIFS('All frames'!$E$2:$E$7074,"EXCLUDE",'All frames'!$B$2:$B$7074,$B33,'All frames'!$C$2:$C$7074,"115") -> 15 | H33: =SUM(D33:G33) -> 92
A34: AS16-116 | B34: 16 | C34: color | D34: =COUNTIFS('All frames'!$E$2:$E$7074,"T1",'All frames'!$B$2:$B$7074,$B34,'All frames'!$C$2:$C$7074,"116") -> 20 | E34: =COUNTIFS('All frames'!$E$2:$E$7074,"T2",'All frames'!$B$2:$B$7074,$B34,'All frames'!$C$2:$C$7074,"116") -> 56 | F34: =COUNTIFS('All frames'!$E$2:$E$7074,"T3",'All frames'!$B$2:$B$7074,$B34,'All frames'!$C$2:$C$7074,"116") -> 0 | G34: =COUNTIFS('All frames'!$E$2:$E$7074,"EXCLUDE",'All frames'!$B$2:$B$7074,$B34,'All frames'!$C$2:$C$7074,"116") -> 86 | H34: =SUM(D34:G34) -> 162
A35: AS16-117 | B35: 16 | C35: color | D35: =COUNTIFS('All frames'!$E$2:$E$7074,"T1",'All frames'!$B$2:$B$7074,$B35,'All frames'!$C$2:$C$7074,"117") -> 13 | E35: =COUNTIFS('All frames'!$E$2:$E$7074,"T2",'All frames'!$B$2:$B$7074,$B35,'All frames'!$C$2:$C$7074,"117") -> 72 | F35: =COUNTIFS('All frames'!$E$2:$E$7074,"T3",'All frames'!$B$2:$B$7074,$B35,'All frames'!$C$2:$C$7074,"117") -> 0 | G35: =COUNTIFS('All frames'!$E$2:$E$7074,"EXCLUDE",'All frames'!$B$2:$B$7074,$B35,'All frames'!$C$2:$C$7074,"117") -> 47 | H35: =SUM(D35:G35) -> 132
A36: AS17-133 | B36: 17 | C36: bw | D36: =COUNTIFS('All frames'!$E$2:$E$7074,"T1",'All frames'!$B$2:$B$7074,$B36,'All frames'!$C$2:$C$7074,"133") -> 31 | E36: =COUNTIFS('All frames'!$E$2:$E$7074,"T2",'All frames'!$B$2:$B$7074,$B36,'All frames'!$C$2:$C$7074,"133") -> 79 | F36: =COUNTIFS('All frames'!$E$2:$E$7074,"T3",'All frames'!$B$2:$B$7074,$B36,'All frames'!$C$2:$C$7074,"133") -> 0 | G36: =COUNTIFS('All frames'!$E$2:$E$7074,"EXCLUDE",'All frames'!$B$2:$B$7074,$B36,'All frames'!$C$2:$C$7074,"133") -> 73 | H36: =SUM(D36:G36) -> 183
A37: AS17-134 | B37: 17 | C37: color | D37: =COUNTIFS('All frames'!$E$2:$E$7074,"T1",'All frames'!$B$2:$B$7074,$B37,'All frames'!$C$2:$C$7074,"134") -> 3 | E37: =COUNTIFS('All frames'!$E$2:$E$7074,"T2",'All frames'!$B$2:$B$7074,$B37,'All frames'!$C$2:$C$7074,"134") -> 7 | F37: =COUNTIFS('All frames'!$E$2:$E$7074,"T3",'All frames'!$B$2:$B$7074,$B37,'All frames'!$C$2:$C$7074,"134") -> 0 | G37: =COUNTIFS('All frames'!$E$2:$E$7074,"EXCLUDE",'All frames'!$B$2:$B$7074,$B37,'All frames'!$C$2:$C$7074,"134") -> 147 | H37: =SUM(D37:G37) -> 157
A38: AS17-135 | B38: 17 | C38: bw | D38: =COUNTIFS('All frames'!$E$2:$E$7074,"T1",'All frames'!$B$2:$B$7074,$B38,'All frames'!$C$2:$C$7074,"135") -> 0 | E38: =COUNTIFS('All frames'!$E$2:$E$7074,"T2",'All frames'!$B$2:$B$7074,$B38,'All frames'!$C$2:$C$7074,"135") -> 112 | F38: =COUNTIFS('All frames'!$E$2:$E$7074,"T3",'All frames'!$B$2:$B$7074,$B38,'All frames'!$C$2:$C$7074,"135") -> 0 | G38: =COUNTIFS('All frames'!$E$2:$E$7074,"EXCLUDE",'All frames'!$B$2:$B$7074,$B38,'All frames'!$C$2:$C$7074,"135") -> 36 | H38: =SUM(D38:G38) -> 148
A39: AS17-136 | B39: 17 | C39: bw | D39: =COUNTIFS('All frames'!$E$2:$E$7074,"T1",'All frames'!$B$2:$B$7074,$B39,'All frames'!$C$2:$C$7074,"136") -> 21 | E39: =COUNTIFS('All frames'!$E$2:$E$7074,"T2",'All frames'!$B$2:$B$7074,$B39,'All frames'!$C$2:$C$7074,"136") -> 54 | F39: =COUNTIFS('All frames'!$E$2:$E$7074,"T3",'All frames'!$B$2:$B$7074,$B39,'All frames'!$C$2:$C$7074,"136") -> 0 | G39: =COUNTIFS('All frames'!$E$2:$E$7074,"EXCLUDE",'All frames'!$B$2:$B$7074,$B39,'All frames'!$C$2:$C$7074,"136") -> 110 | H39: =SUM(D39:G39) -> 185
A40: AS17-137 | B40: 17 | C40: color | D40: =COUNTIFS('All frames'!$E$2:$E$7074,"T1",'All frames'!$B$2:$B$7074,$B40,'All frames'!$C$2:$C$7074,"137") -> 53 | E40: =COUNTIFS('All frames'!$E$2:$E$7074,"T2",'All frames'!$B$2:$B$7074,$B40,'All frames'!$C$2:$C$7074,"137") -> 50 | F40: =COUNTIFS('All frames'!$E$2:$E$7074,"T3",'All frames'!$B$2:$B$7074,$B40,'All frames'!$C$2:$C$7074,"137") -> 0 | G40: =COUNTIFS('All frames'!$E$2:$E$7074,"EXCLUDE",'All frames'!$B$2:$B$7074,$B40,'All frames'!$C$2:$C$7074,"137") -> 59 | H40: =SUM(D40:G40) -> 162
...

Sheet Tier 1
A1: Frame ID | B1: Mission | C1: Magazine | D1: Film | E1: Tier | F1: NASA catalog description | G1: NASA catalog feature | H1: Activity | I1: Lens (mm) | J1: Est. raw TIFF (GB) | K1: Est. processed PNG (GB) | L1: LPI frame page | M1: Quick-look image (ASU) | N1: Raw TIFF URL (ASU) | O1: Processed PNG URL (ASU) | P1: Print JPG URL (LPI)
A2: AS11-40-5851 | B2: 11 | C2: 40 | D2: color | E2: T1 | F2: LUNAR SURFACE | J2: 1.36 | K2: 0.3 | L2: open | M2: open | N2: open | O2: open | P2: open
A3: AS11-40-5889 | B3: 11 | C3: 40 | D3: color | E3: T1 | F3: RIM OF SMALL CRATER; SHALLOW CRATER | J3: 1.36 | K3: 0.3 | L3: open | M3: open | N3: open | O3: open | P3: open
A4: AS11-40-5890 | B4: 11 | C4: 40 | D4: color | E4: T1 | F4: RIM OF SMALL CRATER; SHALLOW CRATER | J4: 1.36 | K4: 0.3 | L4: open | M4: open | N4: open | O4: open | P4: open
A5: AS11-40-5909 | B5: 11 | C5: 40 | D5: color | E5: T1 | F5: SHALLOW CRATER AND ROCKS ON HORIZON | J5: 1.36 | K5: 0.3 | L5: open | M5: open | N5: open | O5: open | P5: open
A6: AS11-40-5910 | B6: 11 | C6: 40 | D6: color | E6: T1 | F6: SHALLOW CRATER AND ROCKS ON HORIZON | J6: 1.36 | K6: 0.3 | L6: open | M6: open | N6: open | O6: open | P6: open
A7: AS11-40-5911 | B7: 11 | C7: 40 | D7: color | E7: T1 | F7: SHALLOW CRATER AND ROCKS ON HORIZON | J7: 1.36 | K7: 0.3 | L7: open | M7: open | N7: open | O7: open | P7: open
A8: AS11-40-5912 | B8: 11 | C8: 40 | D8: color | E8: T1 | F8: LUNAR SURFACE | J8: 1.36 | K8: 0.3 | L8: open | M8: open | N8: open | O8: open | P8: open
A9: AS11-40-5913 | B9: 11 | C9: 40 | D9: color | E9: T1 | F9: LUNAR SURFACE | J9: 1.36 | K9: 0.3 | L9: open | M9: open | N9: open | O9: open | P9: open
A10: AS11-40-5933 | B10: 11 | C10: 40 | D10: color | E10: T1 | F10: LUNAR SURFACE | J10: 1.36 | K10: 0.3 | L10: open | M10: open | N10: open | O10: open | P10: open
A11: AS11-40-5934 | B11: 11 | C11: 40 | D11: color | E11: T1 | F11: LUNAR SURFACE | J11: 1.36 | K11: 0.3 | L11: open | M11: open | N11: open | O11: open | P11: open
A12: AS11-40-5937 | B12: 11 | C12: 40 | D12: color | E12: T1 | F12: LUNAR SURFACE | J12: 1.36 | K12: 0.3 | L12: open | M12: open | N12: open | O12: open | P12: open
A13: AS11-40-5938 | B13: 11 | C13: 40 | D13: color | E13: T1 | F13: LUNAR SURFACE | J13: 1.36 | K13: 0.3 | L13: open | M13: open | N13: open | O13: open | P13: open
... A20: AS11-40-5960 | B20: 11 | C20: 40 | D20: color | E20: T1 | F20: LUNAR SURFACE | J20: 1.36 | K20: 0.3 | L20: open | M20: open | N20: open | O20: open | P20: open
A21: AS12-46-6722 | B21: 12 | C21: 46 | D21: color | E21: T1 | F21: LUNAR SURFACE | I21: 60 | J21: 1.36 | K21: 0.3 | L21: open | M21: open | N21: open | O21: open | P21: open
A22: AS12-46-6833 | B22: 12 | C22: 46 | D22: color | E22: T1 | F22: LUNAR SURFACE | I22: 60 | J22: 1.36 | K22: 0.3 | L22: open | M22: open | N22: open | O22: open | P22: open
A23: AS12-46-6834 | B23: 12 | C23: 46 | D23: color | E23: T1 | F23: LUNAR SURFACE | I23: 60 | J23: 1.36 | K23: 0.3 | L23: open | M23: open | N23: open | O23: open | P23: open
A24: AS12-46-6835 | B24: 12 | C24: 46 | D24: color | E24: T1 | F24: LUNAR SURFACE | I24: 60 | J24: 1.36 | K24: 0.3 | L24: open | M24: open | N24: open | O24: open | P24: open
A25: AS12-47-6937 | B25: 12 | C25: 47 | D25: color | E25: T1 | F25: LUNAR SURFACE | J25: 1.36 | K25: 0.3 | L25: open | M25: open | N25: open | O25: open | P25: open
A26: AS12-48-7047 | B26: 12 | C26: 48 | D26: bw | E26: T1 | F26: VIEW OF LUNAR TERRAIN | J26: 0.348 | K26: 0.17 | L26: open | M26: open | N26: open | O26: open | P26: open
A27: AS12-48-7075 | B27: 12 | C27: 48 | D27: bw | E27: T1 | F27: LUNAR TERRAIN | J27: 0.348 | K27: 0.17 | L27: open | M27: open | N27: open | O27: open | P27: open
A28: AS12-48-7076 | B28: 12 | C28: 48 | D28: bw | E28: T1 | F28: LUNAR TERRAIN | J28: 0.348 | K28: 0.17 | L28: open | M28: open | N28: open | O28: open | P28: open
A29: AS12-48-7146 | B29: 12 | C29: 48 | D29: bw | E29: T1 | G29: BLOCKSURVEYOR III | J29: 0.348 | K29: 0.17 | L29: open | M29: open | N29: open | O29: open | P29: open
A30: AS12-49-7172 | B30: 12 | C30: 49 | D30: bw | E30: T1 | F30: LUNAR TERRAIN | J30: 0.348 | K30: 0.17 | L30: open | M30: open | N30: open | O30: open
A31: AS12-49-7174 | B31: 12 | C31: 49 | D31: bw | E31: T1 | F31: VIEW INTO HEAD | G31: HEAD | J31: 0.348 | K31: 0.17 | L31: open | M31: open | N31: open | O31: open
A32: AS12-49-7175 | B32: 12 | C32: 49 | D32: bw | E32: T1 | F32: VIEW INTO HEAD | G32: HEAD | J32: 0.348 | K32: 0.17 | L32: open | M32: open | N32: open | O32: open
A33: AS12-49-7176 | B33: 12 | C33: 49 | D33: bw | E33: T1 | F33: VIEW INTO HEAD | G33: HEAD | J33: 0.348 | K33: 0.17 | L33: open | M33: open | N33: open | O33: open
A34: AS12-49-7177 | B34: 12 | C34: 49 | D34: bw | E34: T1 | F34: VIEW INTO HEAD | G34: HEAD | J34: 0.348 | K34: 0.17 | L34: open | M34: open | N34: open | O34: open
A35: AS12-49-7178 | B35: 12 | C35: 49 | D35: bw | E35: T1 | F35: VIEW INTO HEAD | G35: HEAD | J35: 0.348 | K35: 0.17 | L35: open | M35: open | N35: open | O35: open
A36: AS12-49-7179 | B36: 12 | C36: 49 | D36: bw | E36: T1 | F36: VIEW INTO HEAD | G36: HEAD | J36: 0.348 | K36: 0.17 | L36: open | M36: open | N36: open | O36: open
A37: AS12-49-7180 | B37: 12 | C37: 49 | D37: bw | E37: T1 | F37: VIEW INTO HEAD | G37: HEAD | J37: 0.348 | K37: 0.17 | L37: open | M37: open | N37: open | O37: open
A38: AS12-49-7181 | B38: 12 | C38: 49 | D38: bw | E38: T1 | F38: VIEW INTO HEAD | G38: HEAD | J38: 0.348 | K38: 0.17 | L38: open | M38: open | N38: open | O38: open
A39: AS12-49-7182 | B39: 12 | C39: 49 | D39: bw | E39: T1 | F39: VIEW INTO HEAD | G39: HEAD | J39: 0.348 | K39: 0.17 | L39: open | M39: open | N39: open | O39: open
A40: AS12-49-7184 | B40: 12 | C40: 49 | D40: bw | E40: T1 | F40: VIEW INTO HEAD | G40: HEAD | J40: 0.348 | K40: 0.17 | L40: open | M40: open | N40: open | O40: open
A41: AS12-49-7185 | B41: 12 | C41: 49 | D41: bw | E41: T1 | F41: VIEW INTO HEAD | G41: HEAD | J41: 0.348 | K41: 0.17 | L41: open | M41: open | N41: open | O41: open
A42: AS12-49-7186 | B42: 12 | C42: 49 | D42: bw | E42: T1 | F42: VIEW INTO HEAD | G42: HEAD | J42: 0.348 | K42: 0.17 | L42: open | M42: open | N42: open | O42: open
A43: AS12-49-7188 | B43: 12 | C43: 49 | D43: bw | E43: T1 | F43: VIEW INTO HEAD | G43: HEAD | J43: 0.348 | K43: 0.17 | L43: open | M43: open | N43: open | O43: open
A44: AS12-49-7201 | B44: 12 | C44: 49 | D44: bw | E44: T1 | F44: VIEW OF LUNAR SURFACE | J44: 0.348 | K44: 0.17 | L44: open | M44: open | N44: open | O44: open
A45: AS12-49-7202 | B45: 12 | C45: 49 | D45: bw | E45: T1 | F45: VIEW OF LUNAR SURFACE | J45: 0.348 | K45: 0.17 | L45: open | M45: open | N45: open | O45: open
A46: AS12-49-7203 | B46: 12 | C46: 49 | D46: bw | E46: T1 | F46: VIEW OF LUNAR SURFACE | J46: 0.348 | K46: 0.17 | L46: open | M46: open | N46: open | O46: open
...

Sheet Tier 2
A1: Frame ID | B1: Mission | C1: Magazine | D1: Film | E1: Tier | F1: Caution flags | G1: NASA catalog description | H1: NASA catalog feature | I1: Activity | J1: Lens (mm) | K1: Est. raw TIFF (GB) | L1: Est. processed PNG (GB) | M1: LPI frame page | N1: Quick-look image (ASU) | O1: Raw TIFF URL (ASU) | P1: Processed PNG URL (ASU) | Q1: Print JPG URL (LPI)
A2: AS11-40-5906 | B2: 11 | C2: 40 | D2: color | E2: T2 | F2: sample documentation (gnomon likely) [ALSJ caption] | G2: LUNAR SURFACE | K2: 1.36 | L2: 0.3 | M2: open | N2: open | O2: open | P2: open | Q2: open
A3: AS11-40-5941 | B3: 11 | C3: 40 | D3: color | E3: T2 | F3: sample documentation (gnomon likely) [ALSJ caption] | G3: LUNAR SURFACE | K3: 1.36 | L3: 0.3 | M3: open | N3: open | O3: open | P3: open | Q3: open
A4: AS11-40-5958 | B4: 11 | C4: 40 | D4: color | E4: T2 | F4: crew member named (Neil) [ALSJ caption]; sample documentation (gnomon likely) [ALSJ caption] | G4: SMALL CRATER WITH ROCKY BOTTOM | K4: 1.36 | L4: 0.3 | M4: open | N4: open | O4: open | P4: open | Q4: open
A5: AS12-46-6723 | B5: 12 | C5: 46 | D5: color | E5: T2 | F5: sample documentation (gnomon likely) [ALSJ caption] | G5: LUNAR SURFACE | J5: 60 | K5: 1.36 | L5: 0.3 | M5: open | N5: open | O5: open | P5: open | Q5: open
A6: AS12-46-6732 | B6: 12 | C6: 46 | D6: color | E6: T2 | F6: taken near LM, rover, or ALSEP [NASA catalog (LPI)] | G6: 16 FRAME PAN NEAR LUNAR MODULE; PAN | J6: 60 | K6: 1.36 | L6: 0.3 | M6: open | N6: open | O6: open | P6: open | Q6: open
A7: AS12-46-6734 | B7: 12 | C7: 46 | D7: color | E7: T2 | F7: taken near LM, rover, or ALSEP [NASA catalog (LPI)] | G7: 16 FRAME PAN NEAR LUNAR MODULE; PAN | J7: 60 | K7: 1.36 | L7: 0.3 | M7: open | N7: open | O7: open | P7: open | Q7: open
A8: AS12-46-6736 | B8: 12 | C8: 46 | D8: color | E8: T2 | F8: crew member named (Al) [ALSJ caption]; taken near LM, rover, or ALSEP [NASA catalog (LPI)] | G8: 16 FRAME PAN NEAR LUNAR MODULE; PAN | J8: 60 | K8: 1.36 | L8: 0.3 | M8: open | N8: open | O8: open | P8: open | Q8: open
A9: AS12-46-6743 | B9: 12 | C9: 46 | D9: color | E9: T2 | F9: taken near LM, rover, or ALSEP [NASA catalog (LPI)] | G9: 16 FRAME PAN NEAR LUNAR MODULE; PAN | J9: 60 | K9: 1.36 | L9: 0.3 | M9: open | N9: open | O9: open | P9: open | Q9: open
A10: AS12-46-6744 | B10: 12 | C10: 46 | D10: color | E10: T2 | F10: taken near LM, rover, or ALSEP [NASA catalog (LPI)] | G10: 16 FRAME PAN NEAR LUNAR MODULE; PAN | J10: 60 | K10: 1.36 | L10: 0.3 | M10: open | N10: open | O10: open | P10: open | Q10: open
A11: AS12-46-6745 | B11: 12 | C11: 46 | D11: color | E11: T2 | F11: taken near LM, rover, or ALSEP [NASA catalog (LPI)] | G11: END 16 FRAME PAN NEAR LUNAR MODULE; PAN | J11: 60 | K11: 1.36 | L11: 0.3 | M11: open | N11: open | O11: open | P11: open | Q11: open
A12: AS12-46-6747 | B12: 12 | C12: 46 | D12: color | E12: T2 | F12: taken near LM, rover, or ALSEP [NASA catalog (LPI)] | G12: 18 FRAME PAN NEAR LUNAR MODULE; PAN | J12: 60 | K12: 1.36 | L12: 0.3 | M12: open | N12: open | O12: open | P12: open | Q12: open
A13: AS12-46-6758 | B13: 12 | C13: 46 | D13: color | E13: T2 | F13: crew member named (Pete) [ALSJ caption]; taken near LM, rover, or ALSEP [NASA catalog (LPI)] | G13: 18 FRAME PAN NEAR LUNAR MODULE; PAN | J13: 60 | K13: 1.36 | L13: 0.3 | M13: open | N13: open | O13: open | P13: open | Q13: open
A14: AS12-46-6759 | B14: 12 | C14: 46 | D14: color | E14: T2 | F14: crew member named (Pete) [ALSJ caption]; taken near LM, rover, or ALSEP [NASA catalog (LPI)] | G14: 18 FRAME PAN NEAR LUNAR MODULE; PAN | J14: 60 | K14: 1.36 | L14: 0.3 | M14: open | N14: open | O14: open | P14: open | Q14: open
A15: AS12-46-6760 | B15: 12 | C15: 46 | D15: color | E15: T2 | F15: crew member named (Pete) [ALSJ caption]; taken near LM, rover, or ALSEP [NASA catalog (LPI)] | G15: 18 FRAME PAN NEAR LUNAR MODULE; PAN | J15: 60 | K15: 1.36 | L15: 0.3 | M15: open | N15: open | O15: open | P15: open | Q15: open
A16: AS12-46-6761 | B16: 12 | C16: 46 | D16: color | E16: T2 | F16: crew member named (Pete) [ALSJ caption]; taken near LM, rover, or ALSEP [NASA catalog (LPI)] | G16: 18 FRAME PAN NEAR LUNAR MODULE; PAN | J16: 60 | K16: 1.36 | L16: 0.3 | M16: open | N16: open | O16: open | P16: open | Q16: open
... A50: AS12-46-6852 | B50: 12 | C50: 46 | D50: color | E50: T2 | F50: taken near LM, rover, or ALSEP [NASA catalog (LPI)] | G50: 8 FRAME PAN NW OF ALSEP - END; PAN | J50: 60 | K50: 1.36 | L50: 0.3 | M50: open | N50: open | O50: open | P50: open | Q50: open
A51: AS12-47-6895 | B51: 12 | C51: 47 | D51: color | E51: T2 | F51: crew member named (Al) [ALSJ caption]; crew member named (Bean) [ALSJ caption] | H51: HILBERTMEITNERPASTEUR | K51: 1.36 | L51: 0.3 | M51: open | N51: open | O51: open | P51: open | Q51: open
A52: AS12-47-6933 | B52: 12 | C52: 47 | D52: color | E52: T2 | F52: sample documentation (gnomon likely) [ALSJ caption] | G52: LUNAR SURFACE | K52: 1.36 | L52: 0.3 | M52: open | N52: open | O52: open | P52: open | Q52: open
A53: AS12-47-6934 | B53: 12 | C53: 47 | D53: color | E53: T2 | F53: sample documentation (gnomon likely) [ALSJ caption] | G53: LUNAR SURFACE | K53: 1.36 | L53: 0.3 | M53: open | N53: open | O53: open | P53: open | Q53: open
A54: AS12-47-6935 | B54: 12 | C54: 47 | D54: color | E54: T2 | F54: sample documentation (gnomon likely) [ALSJ caption] | G54: LUNAR SURFACE | K54: 1.36 | L54: 0.3 | M54: open | N54: open | O54: open | P54: open | Q54: open
A55: AS12-47-6936 | B55: 12 | C55: 47 | D55: color | E55: T2 | F55: crew member named (Al) [ALSJ caption] | G55: LUNAR SURFACE | K55: 1.36 | L55: 0.3 | M55: open | N55: open | O55: open | P55: open | Q55: open
A56: AS12-47-6938 | B56: 12 | C56: 47 | D56: color | E56: T2 | F56: crew member named (Al) [ALSJ caption]; crew member named (Pete) [ALSJ caption] | G56: LUNAR SURFACE | K56: 1.36 | L56: 0.3 | M56: open | N56: open | O56: open | P56: open | Q56: open
A57: AS12-47-6939 | B57: 12 | C57: 47 | D57: color | E57: T2 | F57: sample documentation (gnomon likely) [ALSJ caption] | G57: LUNAR SURFACE | K57: 1.36 | L57: 0.3 | M57: open | N57: open | O57: open | P57: open | Q57: open
A58: AS12-47-6940 | B58: 12 | C58: 47 | D58: color | E58: T2 | F58: sample documentation (gnomon likely) [ALSJ caption] | G58: LUNAR SURFACE | K58: 1.36 | L58: 0.3 | M58: open | N58: open | O58: open | P58: open | Q58: open
A59: AS12-47-6942 | B59: 12 | C59: 47 | D59: color | E59: T2 | F59: taken near LM, rover, or ALSEP [NASA catalog (LPI)] | G59: 2 OF 20-FRAME PAN NEAR LUNAR MODULE; PAN | K59: 1.36 | L59: 0.3 | M59: open | N59: open | O59: open | P59: open | Q59: open
A60: AS12-47-6944 | B60: 12 | C60: 47 | D60: color | E60: T2 | F60: taken near LM, rover, or ALSEP [NASA catalog (LPI)] | G60: 4 OF 20-FRAME PAN NEAR LUNAR MODULE; PAN | K60: 1.36 | L60: 0.3 | M60: open | N60: open | O60: open | P60: open | Q60: open
A61: AS12-47-6946 | B61: 12 | C61: 47 | D61: color | E61: T2 | F61: taken near LM, rover, or ALSEP [NASA catalog (LPI)] | G61: 6 OF 20-FRAME PAN NEAR LUNAR MODULE; PAN | K61: 1.36 | L61: 0.3 | M61: open | N61: open | O61: open | P61: open | Q61: open
A62: AS12-47-6959 | B62: 12 | C62: 47 | D62: color | E62: T2 | F62: taken near LM, rover, or ALSEP [ALSJ caption]; taken near LM, rover, or ALSEP [NASA catalog (LPI)] | G62: 19 OF 20-FRAME PAN NEAR LUNAR MODULE; PAN | K62: 1.36 | L62: 0.3 | M62: open | N62: open | O62: open | P62: open | Q62: open
A63: AS12-47-6960 | B63: 12 | C63: 47 | D63: color | E63: T2 | F63: taken near LM, rover, or ALSEP [NASA catalog (LPI)] | G63: 20 OF 20-FRAME PAN NEAR LUNAR MODULE; PAN | K63: 1.36 | L63: 0.3 | M63: open | N63: open | O63: open | P63: open | Q63: open
... A85: AS12-48-7059 | B85: 12 | C85: 48 | D85: bw | E85: T2 | F85: sample documentation (gnomon likely) [ALSJ caption] | G85: CRATER ON LUNAR SURFACE | K85: 0.348 | L85: 0.17 | M85: open | N85: open | O85: open | P85: open | Q85: open
A86: AS12-49-7212 | B86: 12 | C86: 49 | D86: bw | E86: T2 | F86: crew member named (Al) [ALSJ caption] | G86: VIEW OF LUNAR SURFACE | K86: 0.348 | L86: 0.17 | M86: open | N86: open | O86: open | P86: open
A87: AS12-49-7255 | B87: 12 | C87: 49 | D87: bw | E87: T2 | F87: sample documentation (gnomon likely) [ALSJ caption] | G87: LUNAR TERRAIN | K87: 0.348 | L87: 0.17 | M87: open | N87: open | O87: open | P87: open | Q87: open
A88: AS12-49-7262 | B88: 12 | C88: 49 | D88: bw | E88: T2 | F88: crew member named (Pete) [ALSJ caption]; taken from moving rover [ALSJ caption] | G88: LUNAR TERRAIN | K88: 0.348 | L88: 0.17 | M88: open | N88: open | O88: open | P88: open | Q88: open
A89: AS12-49-7263 | B89: 12 | C89: 49 | D89: bw | E89: T2 | F89: crew member named (Pete) [ALSJ caption] | G89: SHARP | K89: 0.348 | L89: 0.17 | M89: open | N89: open | O89: open | P89: open | Q89: open
A90: AS12-49-7266 | B90: 12 | C90: 49 | D90: bw | E90: T2 | F90: sample documentation (gnomon likely) [ALSJ caption] | G90: SHARP | K90: 0.348 | L90: 0.17 | M90: open | N90: open | O90: open | P90: open | Q90: open
A91: AS12-49-7270 | B91: 12 | C91: 49 | D91: bw | E91: T2 | F91: sample documentation (gnomon likely) [ALSJ caption] | G91: SHARP | K91: 0.348 | L91: 0.17 | M91: open | N91: open | O91: open | P91: open | Q91: open
A92: AS12-49-7271 | B92: 12 | C92: 49 | D92: bw | E92: T2 | F92: crew member named (Pete) [ALSJ caption] | G92: SHARP | K92: 0.348 | L92: 0.17 | M92: open | N92: open | O92: open | P92: open | Q92: open
A93: AS12-49-7272 | B93: 12 | C93: 49 | D93: bw | E93: T2 | F93: sample documentation (gnomon likely) [ALSJ caption] | G93: SHARP | K93: 0.348 | L93: 0.17 | M93: open | N93: open | O93: open | P93: open | Q93: open
A94: AS12-49-7275 | B94: 12 | C94: 49 | D94: bw | E94: T2 | F94: sample documentation (gnomon likely) [ALSJ caption] | G94: SHARP | K94: 0.348 | L94: 0.17 | M94: open | N94: open | O94: open | P94: open | Q94: open
...

Sheet All frames
A1: Frame ID | B1: Mission | C1: Magazine | D1: Film | E1: Tier | F1: Exclusion reasons | G1: Caution flags | H1: NASA catalog description | I1: NASA catalog feature | J1: Activity | K1: Lens (mm) | L1: Est. raw TIFF (GB) | M1: Est. processed PNG (GB) | N1: LPI frame page | O1: Quick-look image (ASU) | P1: Raw TIFF URL (ASU) | Q1: Processed PNG URL (ASU) | R1: Print JPG URL (LPI)
A2: AS11-40-5851 | B2: 11 | C2: 40 | D2: color | E2: T1 | H2: LUNAR SURFACE | L2: 1.36 | M2: 0.3 | N2: open | O2: open | P2: open | Q2: open | R2: open
A3: AS11-40-5889 | B3: 11 | C3: 40 | D3: color | E3: T1 | H3: RIM OF SMALL CRATER; SHALLOW CRATER | L3: 1.36 | M3: 0.3 | N3: open | O3: open | P3: open | Q3: open | R3: open
A4: AS11-40-5890 | B4: 11 | C4: 40 | D4: color | E4: T1 | H4: RIM OF SMALL CRATER; SHALLOW CRATER | L4: 1.36 | M4: 0.3 | N4: open | O4: open | P4: open | Q4: open | R4: open
A5: AS11-40-5909 | B5: 11 | C5: 40 | D5: color | E5: T1 | H5: SHALLOW CRATER AND ROCKS ON HORIZON | L5: 1.36 | M5: 0.3 | N5: open | O5: open | P5: open | Q5: open | R5: open
A6: AS11-40-5910 | B6: 11 | C6: 40 | D6: color | E6: T1 | H6: SHALLOW CRATER AND ROCKS ON HORIZON | L6: 1.36 | M6: 0.3 | N6: open | O6: open | P6: open | Q6: open | R6: open
A7: AS11-40-5911 | B7: 11 | C7: 40 | D7: color | E7: T1 | H7: SHALLOW CRATER AND ROCKS ON HORIZON | L7: 1.36 | M7: 0.3 | N7: open | O7: open | P7: open | Q7: open | R7: open
A8: AS11-40-5912 | B8: 11 | C8: 40 | D8: color | E8: T1 | H8: LUNAR SURFACE | L8: 1.36 | M8: 0.3 | N8: open | O8: open | P8: open | Q8: open | R8: open
A9: AS11-40-5913 | B9: 11 | C9: 40 | D9: color | E9: T1 | H9: LUNAR SURFACE | L9: 1.36 | M9: 0.3 | N9: open | O9: open | P9: open | Q9: open | R9: open
A10: AS11-40-5933 | B10: 11 | C10: 40 | D10: color | E10: T1 | H10: LUNAR SURFACE | L10: 1.36 | M10: 0.3 | N10: open | O10: open | P10: open | Q10: open | R10: open
A11: AS11-40-5934 | B11: 11 | C11: 40 | D11: color | E11: T1 | H11: LUNAR SURFACE | L11: 1.36 | M11: 0.3 | N11: open | O11: open | P11: open | Q11: open | R11: open
A12: AS11-40-5937 | B12: 11 | C12: 40 | D12: color | E12: T1 | H12: LUNAR SURFACE | L12: 1.36 | M12: 0.3 | N12: open | O12: open | P12: open | Q12: open | R12: open
A13: AS11-40-5938 | B13: 11 | C13: 40 | D13: color | E13: T1 | H13: LUNAR SURFACE | L13: 1.36 | M13: 0.3 | N13: open | O13: open | P13: open | Q13: open | R13: open
... A20: AS11-40-5960 | B20: 11 | C20: 40 | D20: color | E20: T1 | H20: LUNAR SURFACE | L20: 1.36 | M20: 0.3 | N20: open | O20: open | P20: open | Q20: open | R20: open
A21: AS12-46-6722 | B21: 12 | C21: 46 | D21: color | E21: T1 | H21: LUNAR SURFACE | K21: 60 | L21: 1.36 | M21: 0.3 | N21: open | O21: open | P21: open | Q21: open | R21: open
A22: AS12-46-6833 | B22: 12 | C22: 46 | D22: color | E22: T1 | H22: LUNAR SURFACE | K22: 60 | L22: 1.36 | M22: 0.3 | N22: open | O22: open | P22: open | Q22: open | R22: open
A23: AS12-46-6834 | B23: 12 | C23: 46 | D23: color | E23: T1 | H23: LUNAR SURFACE | K23: 60 | L23: 1.36 | M23: 0.3 | N23: open | O23: open | P23: open | Q23: open | R23: open
A24: AS12-46-6835 | B24: 12 | C24: 46 | D24: color | E24: T1 | H24: LUNAR SURFACE | K24: 60 | L24: 1.36 | M24: 0.3 | N24: open | O24: open | P24: open | Q24: open | R24: open
A25: AS12-47-6937 | B25: 12 | C25: 47 | D25: color | E25: T1 | H25: LUNAR SURFACE | L25: 1.36 | M25: 0.3 | N25: open | O25: open | P25: open | Q25: open | R25: open
A26: AS12-48-7047 | B26: 12 | C26: 48 | D26: bw | E26: T1 | H26: VIEW OF LUNAR TERRAIN | L26: 0.348 | M26: 0.17 | N26: open | O26: open | P26: open | Q26: open | R26: open
A27: AS12-48-7075 | B27: 12 | C27: 48 | D27: bw | E27: T1 | H27: LUNAR TERRAIN | L27: 0.348 | M27: 0.17 | N27: open | O27: open | P27: open | Q27: open | R27: open
A28: AS12-48-7076 | B28: 12 | C28: 48 | D28: bw | E28: T1 | H28: LUNAR TERRAIN | L28: 0.348 | M28: 0.17 | N28: open | O28: open | P28: open | Q28: open | R28: open
A29: AS12-48-7146 | B29: 12 | C29: 48 | D29: bw | E29: T1 | I29: BLOCKSURVEYOR III | L29: 0.348 | M29: 0.17 | N29: open | O29: open | P29: open | Q29: open | R29: open
A30: AS12-49-7172 | B30: 12 | C30: 49 | D30: bw | E30: T1 | H30: LUNAR TERRAIN | L30: 0.348 | M30: 0.17 | N30: open | O30: open | P30: open | Q30: open
A31: AS12-49-7174 | B31: 12 | C31: 49 | D31: bw | E31: T1 | H31: VIEW INTO HEAD | I31: HEAD | L31: 0.348 | M31: 0.17 | N31: open | O31: open | P31: open | Q31: open
A32: AS12-49-7175 | B32: 12 | C32: 49 | D32: bw | E32: T1 | H32: VIEW INTO HEAD | I32: HEAD | L32: 0.348 | M32: 0.17 | N32: open | O32: open | P32: open | Q32: open
A33: AS12-49-7176 | B33: 12 | C33: 49 | D33: bw | E33: T1 | H33: VIEW INTO HEAD | I33: HEAD | L33: 0.348 | M33: 0.17 | N33: open | O33: open | P33: open | Q33: open
A34: AS12-49-7177 | B34: 12 | C34: 49 | D34: bw | E34: T1 | H34: VIEW INTO HEAD | I34: HEAD | L34: 0.348 | M34: 0.17 | N34: open | O34: open | P34: open | Q34: open
A35: AS12-49-7178 | B35: 12 | C35: 49 | D35: bw | E35: T1 | H35: VIEW INTO HEAD | I35: HEAD | L35: 0.348 | M35: 0.17 | N35: open | O35: open | P35: open | Q35: open
A36: AS12-49-7179 | B36: 12 | C36: 49 | D36: bw | E36: T1 | H36: VIEW INTO HEAD | I36: HEAD | L36: 0.348 | M36: 0.17 | N36: open | O36: open | P36: open | Q36: open
A37: AS12-49-7180 | B37: 12 | C37: 49 | D37: bw | E37: T1 | H37: VIEW INTO HEAD | I37: HEAD | L37: 0.348 | M37: 0.17 | N37: open | O37: open | P37: open | Q37: open
A38: AS12-49-7181 | B38: 12 | C38: 49 | D38: bw | E38: T1 | H38: VIEW INTO HEAD | I38: HEAD | L38: 0.348 | M38: 0.17 | N38: open | O38: open | P38: open | Q38: open
A39: AS12-49-7182 | B39: 12 | C39: 49 | D39: bw | E39: T1 | H39: VIEW INTO HEAD | I39: HEAD | L39: 0.348 | M39: 0.17 | N39: open | O39: open | P39: open | Q39: open
A40: AS12-49-7184 | B40: 12 | C40: 49 | D40: bw | E40: T1 | H40: VIEW INTO HEAD | I40: HEAD | L40: 0.348 | M40: 0.17 | N40: open | O40: open | P40: open | Q40: open
A41: AS12-49-7185 | B41: 12 | C41: 49 | D41: bw | E41: T1 | H41: VIEW INTO HEAD | I41: HEAD | L41: 0.348 | M41: 0.17 | N41: open | O41: open | P41: open | Q41: open
A42: AS12-49-7186 | B42: 12 | C42: 49 | D42: bw | E42: T1 | H42: VIEW INTO HEAD | I42: HEAD | L42: 0.348 | M42: 0.17 | N42: open | O42: open | P42: open | Q42: open
A43: AS12-49-7188 | B43: 12 | C43: 49 | D43: bw | E43: T1 | H43: VIEW INTO HEAD | I43: HEAD | L43: 0.348 | M43: 0.17 | N43: open | O43: open | P43: open | Q43: open
A44: AS12-49-7201 | B44: 12 | C44: 49 | D44: bw | E44: T1 | H44: VIEW OF LUNAR SURFACE | L44: 0.348 | M44: 0.17 | N44: open | O44: open | P44: open | Q44: open
A45: AS12-49-7202 | B45: 12 | C45: 49 | D45: bw | E45: T1 | H45: VIEW OF LUNAR SURFACE | L45: 0.348 | M45: 0.17 | N45: open | O45: open | P45: open | Q45: open
A46: AS12-49-7203 | B46: 12 | C46: 49 | D46: bw | E46: T1 | H46: VIEW OF LUNAR SURFACE | L46: 0.348 | M46: 0.17 | N46: open | O46: open | P46: open | Q46: open
...
